Workbook

Sheet Cover
B2: TEST CASE
B4: Project Name | C4: Fly Booking System | F4: Creator
B5: Project Code | C5: FLYBOOKING | F5: Reviewer/Approver
B6: Document Code | C6: =C5&"_"&"XXX"&"_"&"vx.x" -> FLYBOOKING_XXX_vx.x | F6: Date
F7: Version
B9: History
B10: No | C10: Function Name | D10: Sheet Name | E10: A, D, M | F10: Description | G10: Version | H10: Reference
B11: 1 | C11: Đặt vé máy bay (Search - Results - Details - Confirm) | D11: FlyBookingTestCase!A1 | H11: Fly_Booking_Requirements_V6.docx

Sheet FlyBookingTestCase
A2: Module Code | B2: FLY | H2: Pass
A3: Test requirement | B3: Kiểm tra chức năng đặt vé máy bay (Search, Search Results, Personal Details, Confirm) - Fly_Booking_Requirements_V6.docx | H3: Fail
A4: Environment | B4: Pass | C4: Fail | D4: Untested | E4: N/A | F4: Total
A5: IE | B5: =COUNTIF(I15:I1003,"Pass") -> 0 | C5: =COUNTIF(I15:I1003,"Fail") -> 0 | D5: =COUNTIF(I15:I1003,"Untested") -> 0 | E5: =COUNTIF(I15:I1003,"N/A") -> 51 | F5: =COUNTA(B15:B1003) -> 51
A6: Chrome | B6: =COUNTIF(R15:R1003,"Pass") -> 44 | C6: =COUNTIF(R15:R1003,"Fail") -> 6 | D6: =COUNTIF(R15:R1003,"Untested") -> 1 | E6: =COUNTIF(R15:R1003,"N/A") -> 0 | F6: =COUNTA(B15:B1003) -> 51
A7: Firefox | B7: =COUNTIF(S15:S1003,"Pass") -> 0 | C7: =COUNTIF(S15:S1003,"Fail") -> 0 | D7: =COUNTIF(S15:S1003,"Untested") -> 0 | E7: =COUNTIF(S15:S1003,"N/A") -> 51 | F7: =COUNTA(B15:B1003) -> 51 | H7: N/A
A8: Tester
A9: Date
A11: ID | B11: Test Case Description | C11: Test Case Procedure | D11: Pre - Condition | E11: Expected Result | F11: Test Data | G11: Test Result | I11: Test Results
I13: IE | R13: Chrome | S13: Firefox
A15: SEARCH - Nơi đi / Nơi đến
A16: FLY_01 | B16: Gõ từ 3 ký tự trở lên ở trường Nơi đi hiển thị gợi ý | C16: 1. Vào màn hình Search 2. Gõ 3 ký tự vào trường Nơi đi, ví dụ 'HAN' | D16: Đang ở màn hình Search | E16: Hệ thống hiển thị danh sách gợi ý gồm Tên và Mã sân bay, ví dụ 'Noi Bai airport (HAN)' | F16: Nơi đi: HAN | G16: Danh sách gợi ý hiển thị đúng định dạng 'Tên (Mã)', ví dụ 'Noi Bai airport (HAN)'. | I16: N/A | N16: Pass | R16: Pass | S16: N/A
A17: FLY_02 | B17: Gõ dưới 3 ký tự ở Nơi đi không hiện gợi ý | C17: 1. Gõ 1-2 ký tự vào trường Nơi đi | D17: Đang ở màn hình Search | E17: Hệ thống không hiển thị danh sách gợi ý | F17: Nơi đi: HA | G17: Gõ 2 ký tự chưa thấy gợi ý nào xuất hiện, đúng kỳ vọng. | I17: N/A | N17: Pass | R17: Pass | S17: N/A
A18: FLY_03 | B18: Chọn Nơi đi trùng với Nơi đến | C18: 1. Chọn Nơi đi = HAN 2. Chọn Nơi đến = HAN 3. Điền các trường còn lại và bấm Search | D18: Đang ở màn hình Search | E18: Hệ thống báo lỗi Nơi đi và Nơi đến phải khác nhau, không cho tìm kiếm | F18: Nơi đi=HAN, Nơi đến=HAN | G18: Hệ thống báo lỗi 'Departure and Destination must be different', không cho tìm kiếm. | I18: N/A | N18: Pass | R18: Pass | S18: N/A
A19: FLY_04 | B19: Không nhập Nơi đi hoặc Nơi đến rồi bấm Search | C19: 1. Bỏ trống Nơi đi (hoặc Nơi đến) 2. Điền các trường còn lại 3. Bấm Search | D19: Đang ở màn hình Search | E19: Hệ thống báo lỗi 'Xin hãy thông tin/ Please fulfill the input' | F19: Nơi đi: (trống) | G19: Hệ thống hiển thị đúng thông báo 'Please fulfill the input'. | I19: N/A | N19: Pass | R19: Pass | S19: N/A
A20: SEARCH - Ngày đi / Ngày về | G20: Ô nhập ngày không nhận ký tự bàn phím, chỉ mở Calendar khi click, đúng spec. | I20: N/A | N20: Pass | R20: Pass | S20: N/A
A21: FLY_05 | B21: Chỉ cho chọn Ngày đi qua Calendar, không cho gõ tay | C21: 1. Click vào trường Ngày đi 2. Thử gõ tay ngày bằng bàn phím | D21: Đang ở màn hình Search | E21: Hệ thống không cho gõ tay, chỉ cho chọn qua Calendar popup | F21: Gõ thử: 12/30/2026 | G21: Chọn One way: trường Ngày về bị ẩn ngay lập tức. | I21: N/A | N21: Pass | R21: Pass | S21: N/A
A22: FLY_06 | B22: Chọn One way thì ẩn trường Ngày về | C22: 1. Chọn option One way | D22: Đang ở màn hình Search | E22: Trường Ngày về bị ẩn, chỉ hiện Ngày đi | F22: Trip type: One way | G22: Chọn Round trip: trường Ngày về hiện ra; nếu để trống và bấm Search, hệ thống CHƯA báo lỗi riêng cho Ngày về mà chỉ báo chung 'Please fulfill the input' - chấp nhận được nhưng thông báo chưa cụ thể về trường bị thiếu. | I22: N/A | N22: Pass | R22: Pass | S22: N/A
A23: FLY_07 | B23: Chọn Round trip thì hiện và bắt buộc Ngày về | C23: 1. Chọn option Round trip 2. Không chọn Ngày về 3. Điền các trường còn lại và bấm Search | D23: Đang ở màn hình Search | E23: Trường Ngày về được hiển thị; hệ thống báo lỗi bắt buộc chọn Ngày về nếu để trống | F23: Trip type: Round trip | G23: Hệ thống VẪN CHO tạo tìm kiếm thành công dù Ngày về (19/12) trước Ngày đi (20/12); không hiện thông báo 'Ngày về phải sau ngày đi' như spec yêu cầu. | I23: N/A | N23: Fail | R23: Fail | S23: N/A
A24: FLY_08 | B24: Chọn Ngày về trước hoặc bằng Ngày đi | C24: 1. Chọn Round trip 2. Chọn Ngày đi = 20/12/2026 3. Chọn Ngày về = 20/12/2026 hoặc sớm hơn 4. Bấm Search | D24: Đã chọn Round trip | E24: Hệ thống báo lỗi 'Ngày về phải sau ngày đi' | F24: Ngày đi=20/12/2026, Ngày về=19/12/2026 | G24: Tìm kiếm thành công, không báo lỗi với Ngày về hợp lệ sau Ngày đi. | I24: N/A | N24: Pass | R24: Pass | S24: N/A
A25: FLY_09 | B25: Chọn Ngày về hợp lệ (sau Ngày đi) | C25: 1. Chọn Round trip 2. Chọn Ngày đi = 20/12/2026, Ngày về = 25/12/2026 3. Bấm Search | D25: Đã chọn Round trip | E25: Hệ thống cho phép tìm kiếm, không báo lỗi | F25: Ngày đi=20/12/2026, Ngày về=25/12/2026
A26: SEARCH - Số lượng hành khách | G26: Adults=1, Child=0, Infant=0 hiển thị đúng mặc định. | I26: N/A | N26: Pass | R26: Pass | S26: N/A
A27: FLY_10 | B27: Giá trị mặc định của số lượng hành khách | C27: 1. Mở màn hình Search, quan sát các ô Adults/Child/Infant | D27: Đang ở màn hình Search | E27: Adults mặc định = 1, Child mặc định = 0, Infant mặc định = 0 | F27: (không nhập gì) | G27: Nút '+' ở Adults bị vô hiệu hóa (disable) khi đã đạt giá trị 3, và nút '-' disable khi ở giá trị 1; không cho vượt ngưỡng. | I27: N/A | N27: Pass | R27: Pass | S27: N/A
A28: FLY_11 | B28: Nhập Adults nhỏ hơn 1 hoặc lớn hơn 3 | C28: 1. Thử giảm Adults xuống 0 hoặc tăng lên 4 | D28: Đang ở màn hình Search | E28: Hệ thống chặn, không cho vượt qua khoảng min=1 max=3 (có thể cấu hình được) | F28: Adults: 0 hoặc 4 | G28: Hệ thống KHÔNG kiểm tra ràng buộc 'người lớn >= trẻ em'; vẫn cho tìm kiếm thành công với Adults=1, Child=2. | I28: N/A | N28: Fail | R28: Fail | S28: N/A
A29: FLY_12 | B29: Tổng số trẻ em vượt quá số người lớn | C29: 1. Đặt Adults = 1 2. Đặt Child + Infant > 1 (ví dụ Child=2) 3. Bấm Search | D29: Đang ở màn hình Search | E29: Hệ thống báo lỗi vì 1 người lớn chỉ được đi cùng tối đa 1 trẻ em | F29: Adults=1, Child=2 | G29: Tìm kiếm thành công với Adults=1, Child=1, không báo lỗi. | I29: N/A | N29: Pass | R29: Pass | S29: N/A
A30: FLY_13 | B30: Số lượng hành khách hợp lệ (Adults=1, Child=1) | C30: 1. Đặt Adults=1, Child=1, Infant=0 2. Điền các trường còn lại và bấm Search | D30: Đang ở màn hình Search | E30: Hệ thống cho phép tìm kiếm bình thường | F30: Adults=1, Child=1, Infant=0 | G30: Vì UI dùng stepper (không cho giảm dưới 1), không thể tạo trường hợp Adults=0 trên giao diện; cần Dev xác nhận có con đường nào (ví dụ qua URL/API) để đặt 0 hay không. Tạm để Untested. | I30: N/A | N30: Untested | R30: Untested | S30: N/A
A31: FLY_14 | B31: Bấm Search khi tổng số người = 0 | C31: 1. Đặt Adults=0 (nếu hệ thống cho phép giảm về 0 trước khi validate) 2. Bấm Search | D31: Đang ở màn hình Search | E31: Hệ thống báo lỗi 'Xin hãy thông tin' vì số lượng người = 0 | F31: Adults=0
A32: SEARCH - Loại chuyến đi & Hạng vé | G32: Mặc định đúng là One way và Economy khi vào màn hình Search. | I32: N/A | N32: Pass | R32: Pass | S32: N/A
A33: FLY_15 | B33: Giá trị mặc định của Loại chuyến đi và Hạng vé | C33: 1. Mở màn hình Search, quan sát | D33: Đang ở màn hình Search | E33: Mặc định là One way và hạng Economy | F33: (không nhập gì) | G33: Chọn được Business/First, dropdown cập nhật đúng giá trị đã chọn. | I33: N/A | N33: Pass | R33: Pass | S33: N/A
A34: FLY_16 | B34: Chọn các hạng vé khác Economy | C34: 1. Mở dropdown Hạng vé 2. Chọn Business hoặc First | D34: Đang ở màn hình Search | E34: Hệ thống cho phép chọn và cập nhật đúng lựa chọn (Business/First) | F34: Hạng vé: Business
A35: SEARCH - Nút Search (validate tổng hợp) | G35: Bấm Search khi thiếu cả 3 trường: hệ thống báo 'Please fulfill the input', không điều hướng sang trang kết quả. | I35: N/A | N35: Pass | R35: Pass | S35: N/A
A36: FLY_17 | B36: Bấm Search khi thiếu nhiều trường bắt buộc cùng lúc | C36: 1. Bỏ trống cả Nơi đi, Nơi đến, Ngày đi 2. Bấm Search | D36: Đang ở màn hình Search | E36: Hệ thống báo lỗi 'Xin hãy thông tin/ Please fulfill the input', không thực hiện tìm kiếm | F36: Tất cả đều để trống | G36: Tìm kiếm thành công, điều hướng sang Search Results với danh sách chuyến bay HAN-SGN hiển thị đầy đủ. | I36: N/A | N36: Pass | R36: Pass | S36: N/A
A37: FLY_18 | B37: Tìm kiếm thành công với dữ liệu hợp lệ | C37: 1. Điền đầy đủ: Nơi đi=HAN, Nơi đến=SGN, Ngày đi=20/12/2026, Adults=1, One way, Economy 2. Bấm Search | D37: Đang ở màn hình Search | E37: Hệ thống chuyển sang màn hình Search Results, hiển thị danh sách chuyến bay và giá vé tương ứng | F37: HAN -> SGN, 20/12/2026, Adults=1
A38: SEARCH RESULTS - Bộ lọc (Filter) | G38: Tất cả checkbox Route Stops và Airlines ở trạng thái uncheck mặc định khi vào trang. | I38: N/A | N38: Pass | R38: Pass | S38: N/A
A39: FLY_19 | B39: Các ô filter mặc định ở trạng thái uncheck | C39: 1. Vào màn hình Search Results sau khi tìm kiếm | D39: Đã có kết quả tìm kiếm hiển thị | E39: Tất cả checkbox trong Route Stops và Airlines đều ở trạng thái uncheck | F39: (không thao tác) | G39: Sau khi tick 'Direct', danh sách chỉ còn các chuyến bay không dừng, đúng kỳ vọng. | I39: N/A | N39: Pass | R39: Pass | S39: N/A
A40: FLY_20 | B40: Lọc theo 1 điều kiện Route Stops | C40: 1. Tick chọn 'Direct' | D40: Đang ở màn hình Search Results | E40: Danh sách chỉ hiện các chuyến bay không qua trạm dừng (non-stop) | F40: Route Stops: Direct | G40: Tick Direct + 1 hãng bay: danh sách lọc đúng cả 2 điều kiện (AND giữa nhóm), đúng như Requirement Log đã xác nhận. | I40: N/A | N40: Pass | R40: Pass | S40: N/A
A41: FLY_21 | B41: Lọc kết hợp Route Stops và Airlines (AND giữa 2 nhóm) | C41: 1. Tick 'Direct' trong Route Stops 2. Tick 1 hãng bay cụ thể trong Airlines | D41: Đang ở màn hình Search Results | E41: Danh sách chỉ hiện chuyến bay THỎA CẢ HAI điều kiện: không dừng + đúng hãng bay đã chọn | F41: Route Stops: Direct, Airlines: Delta Air Lines | G41: Đổi Ngày đi và bấm lại Search: danh sách Available Flights cập nhật đúng, tuy nhiên phần 'Date Availability' đề cập trong spec KHÔNG hiển thị trên giao diện thực tế (có thể là tính năng chưa triển khai hoặc spec chưa khớp UI). | I41: N/A | N41: Fail | R41: Fail | S41: N/A
A42: FLY_22 | B42: Bấm lại nút Search ở Search Results để cập nhật kết quả | C42: 1. Thay đổi điều kiện tra cứu (ví dụ đổi Ngày đi) 2. Bấm nút Search trên màn hình Search Results | D42: Đang ở màn hình Search Results | E42: Danh sách chuyến bay (Available Flights) và Date Availability được cập nhật theo điều kiện mới | F42: Đổi Ngày đi sang ngày khác
A43: SEARCH RESULTS - Danh sách chuyến bay | G43: Các trường hiển thị đầy đủ: icon+tên hãng bay, mã chuyến bay, tuyến bay, giờ đi/đến, tag non-stop/transit, giá USD - đúng spec. | I43: N/A | N43: Pass | R43: Pass | S43: N/A
A44: FLY_23 | B44: Kiểm tra thông tin hiển thị của 1 chuyến bay | C44: 1. Quan sát 1 dòng kết quả bất kỳ trong danh sách | D44: Đã có kết quả tìm kiếm | E44: Hiển thị đầy đủ: icon+tên hãng bay, mã số chuyến bay, thông tin đường bay (ví dụ HAN -> SGN), giờ đi/đến, đặc điểm non-stop/transit, giá vé USD | F44: (quan sát UI) | G44: Nút Book Now ở tất cả các dòng đều ở trạng thái enable. | I44: N/A | N44: Pass | R44: Pass | S44: N/A
...

Sheet Summary
B1: SUMMARY
B4: No | C4: Module code | D4: Pass | E4: Fail | F4: Untested | G4: N/A | H4: Number of test cases
B5: 1 | C5: =FlyBookingTestCase!B2 -> FLY | D5: =FlyBookingTestCase!B6 -> 44 | E5: =FlyBookingTestCase!C6 -> 6 | F5: =FlyBookingTestCase!D6 -> 1 | G5: =FlyBookingTestCase!E6 -> 0 | H5: =FlyBookingTestCase!F6 -> 51
C8: Sub total | D8: =SUM(D5:D7) -> 44 | E8: =SUM(E5:E7) -> 6 | F8: =SUM(F5:F7) -> 1 | G8: =SUM(G5:G7) -> 0 | H8: =SUM(H5:H7) -> 51
C10: Test coverage | E10: =(D8+E8)*100/(H8-G8) -> 98.039216 | F10: %
C11: Test successful coverage | E11: =D8*100/(H8-G8) -> 86.27451 | F11: %
